[2025-02-05T04:08:49.019+0000] {taskinstance.py:1159} INFO - Dependencies all met for dep_context=non-requeueable deps ti=<TaskInstance: example_dag.execute_remote_script manual__2025-02-05T04:08:46.639531+00:00 [queued]>
[2025-02-05T04:08:49.021+0000] {taskinstance.py:1159} INFO - Dependencies all met for dep_context=requeueable deps ti=<TaskInstance: example_dag.execute_remote_script manual__2025-02-05T04:08:46.639531+00:00 [queued]>
[2025-02-05T04:08:49.022+0000] {taskinstance.py:1361} INFO - Starting attempt 1 of 2
[2025-02-05T04:08:49.026+0000] {taskinstance.py:1382} INFO - Executing <Task(SSHOperator): execute_remote_script> on 2025-02-05 04:08:46.639531+00:00
[2025-02-05T04:08:49.028+0000] {standard_task_runner.py:57} INFO - Started process 90 to run task
[2025-02-05T04:08:49.029+0000] {standard_task_runner.py:84} INFO - Running: ['***', 'tasks', 'run', 'example_dag', 'execute_remote_script', 'manual__2025-02-05T04:08:46.639531+00:00', '--job-id', '51', '--raw', '--subdir', 'DAGS_FOLDER/example_dag.py', '--cfg-path', '/tmp/tmp8fqb_9za']
[2025-02-05T04:08:49.030+0000] {standard_task_runner.py:85} INFO - Job 51: Subtask execute_remote_script
[2025-02-05T04:08:49.037+0000] {logging_mixin.py:151} WARNING - /home/***/.local/lib/python3.8/site-packages/***/settings.py:195 DeprecationWarning: The sql_alchemy_conn option in [core] has been moved to the sql_alchemy_conn option in [database] - the old setting has been used, but please update your config.
[2025-02-05T04:08:49.049+0000] {task_command.py:415} INFO - Running <TaskInstance: example_dag.execute_remote_script manual__2025-02-05T04:08:46.639531+00:00 [running]> on host 3849bfb82152
[2025-02-05T04:08:49.064+0000] {abstractoperator.py:696} ERROR - Exception rendering Jinja template for task 'execute_remote_script', field 'command'. Template: 'bash /script/date_print.sh'
Traceback (most recent call last):
  File "/home/airflow/.local/lib/python3.8/site-packages/airflow/models/abstractoperator.py", line 688, in _do_render_template_fields
    rendered_content = self.render_template(
  File "/home/airflow/.local/lib/python3.8/site-packages/airflow/template/templater.py", line 153, in render_template
    template = jinja_env.get_template(value)
  File "/home/airflow/.local/lib/python3.8/site-packages/jinja2/environment.py", line 1010, in get_template
    return self._load_template(name, globals)
  File "/home/airflow/.local/lib/python3.8/site-packages/jinja2/environment.py", line 969, in _load_template
    template = self.loader.load(self, name, self.make_globals(globals))
  File "/home/airflow/.local/lib/python3.8/site-packages/jinja2/loaders.py", line 126, in load
    source, filename, uptodate = self.get_source(environment, name)
  File "/home/airflow/.local/lib/python3.8/site-packages/jinja2/loaders.py", line 218, in get_source
    raise TemplateNotFound(template)
jinja2.exceptions.TemplateNotFound: bash /script/date_print.sh
[2025-02-05T04:08:49.065+0000] {taskinstance.py:1943} ERROR - Task failed with exception
Traceback (most recent call last):
  File "/home/airflow/.local/lib/python3.8/site-packages/airflow/models/taskinstance.py", line 1518, in _run_raw_task
    self._execute_task_with_callbacks(context, test_mode, session=session)
  File "/home/airflow/.local/lib/python3.8/site-packages/airflow/models/taskinstance.py", line 1646, in _execute_task_with_callbacks
    task_orig = self.render_templates(context=context)
  File "/home/airflow/.local/lib/python3.8/site-packages/airflow/models/taskinstance.py", line 2291, in render_templates
    original_task.render_template_fields(context)
  File "/home/airflow/.local/lib/python3.8/site-packages/airflow/models/baseoperator.py", line 1244, in render_template_fields
    self._do_render_template_fields(self, self.template_fields, context, jinja_env, set())
  File "/home/airflow/.local/lib/python3.8/site-packages/airflow/utils/session.py", line 77, in wrapper
    return func(*args, session=session, **kwargs)
  File "/home/airflow/.local/lib/python3.8/site-packages/airflow/models/abstractoperator.py", line 688, in _do_render_template_fields
    rendered_content = self.render_template(
  File "/home/airflow/.local/lib/python3.8/site-packages/airflow/template/templater.py", line 153, in render_template
    template = jinja_env.get_template(value)
  File "/home/airflow/.local/lib/python3.8/site-packages/jinja2/environment.py", line 1010, in get_template
    return self._load_template(name, globals)
  File "/home/airflow/.local/lib/python3.8/site-packages/jinja2/environment.py", line 969, in _load_template
    template = self.loader.load(self, name, self.make_globals(globals))
  File "/home/airflow/.local/lib/python3.8/site-packages/jinja2/loaders.py", line 126, in load
    source, filename, uptodate = self.get_source(environment, name)
  File "/home/airflow/.local/lib/python3.8/site-packages/jinja2/loaders.py", line 218, in get_source
    raise TemplateNotFound(template)
jinja2.exceptions.TemplateNotFound: bash /script/date_print.sh
[2025-02-05T04:08:49.068+0000] {taskinstance.py:1400} INFO - Marking task as UP_FOR_RETRY. dag_id=example_dag, task_id=execute_remote_script, execution_date=20250205T040846, start_date=20250205T040849, end_date=20250205T040849
[2025-02-05T04:08:49.072+0000] {standard_task_runner.py:104} ERROR - Failed to execute job 51 for task execute_remote_script (bash /script/date_print.sh; 90)
[2025-02-05T04:08:49.084+0000] {local_task_job_runner.py:228} INFO - Task exited with return code 1
[2025-02-05T04:08:49.091+0000] {taskinstance.py:2784} INFO - 0 downstream tasks scheduled from follow-on schedule check
