[2025-02-05 03:52:14,214] {taskinstance.py:1159} INFO - Dependencies all met for <TaskInstance: example_dag.execute_remote_script manual__2025-02-05T03:52:12.151970+00:00 [queued]>
[2025-02-05 03:52:14,219] {taskinstance.py:1159} INFO - Dependencies all met for <TaskInstance: example_dag.execute_remote_script manual__2025-02-05T03:52:12.151970+00:00 [queued]>
[2025-02-05 03:52:14,219] {taskinstance.py:1356} INFO - 
--------------------------------------------------------------------------------
[2025-02-05 03:52:14,219] {taskinstance.py:1357} INFO - Starting attempt 1 of 2
[2025-02-05 03:52:14,219] {taskinstance.py:1358} INFO - 
--------------------------------------------------------------------------------
[2025-02-05 03:52:14,224] {taskinstance.py:1377} INFO - Executing <Task(SSHOperator): execute_remote_script> on 2025-02-05 03:52:12.151970+00:00
[2025-02-05 03:52:14,226] {standard_task_runner.py:52} INFO - Started process 230 to run task
[2025-02-05 03:52:14,228] {standard_task_runner.py:79} INFO - Running: ['***', 'tasks', 'run', 'example_dag', 'execute_remote_script', 'manual__2025-02-05T03:52:12.151970+00:00', '--job-id', '40', '--raw', '--subdir', 'DAGS_FOLDER/example_dag.py', '--cfg-path', '/tmp/tmpcdzau_o6', '--error-file', '/tmp/tmps0axe9ce']
[2025-02-05 03:52:14,228] {standard_task_runner.py:80} INFO - Job 40: Subtask execute_remote_script
[2025-02-05 03:52:14,259] {task_command.py:369} INFO - Running <TaskInstance: example_dag.execute_remote_script manual__2025-02-05T03:52:12.151970+00:00 [running]> on host 4e60bfee8242
[2025-02-05 03:52:14,275] {taskinstance.py:1889} ERROR - Task failed with exception
Traceback (most recent call last):
  File "/home/airflow/.local/lib/python3.7/site-packages/airflow/models/taskinstance.py", line 1451, in _run_raw_task
    self._execute_task_with_callbacks(context, test_mode)
  File "/home/airflow/.local/lib/python3.7/site-packages/airflow/models/taskinstance.py", line 1555, in _execute_task_with_callbacks
    task_orig = self.render_templates(context=context)
  File "/home/airflow/.local/lib/python3.7/site-packages/airflow/models/taskinstance.py", line 2202, in render_templates
    rendered_task = self.task.render_template_fields(context)
  File "/home/airflow/.local/lib/python3.7/site-packages/airflow/models/baseoperator.py", line 1179, in render_template_fields
    self._do_render_template_fields(self, self.template_fields, context, jinja_env, set())
  File "/home/airflow/.local/lib/python3.7/site-packages/airflow/utils/session.py", line 71, in wrapper
    return func(*args, session=session, **kwargs)
  File "/home/airflow/.local/lib/python3.7/site-packages/airflow/models/abstractoperator.py", line 348, in _do_render_template_fields
    seen_oids,
  File "/home/airflow/.local/lib/python3.7/site-packages/airflow/models/abstractoperator.py", line 385, in render_template
    template = jinja_env.get_template(value)
  File "/home/airflow/.local/lib/python3.7/site-packages/jinja2/environment.py", line 997, in get_template
    return self._load_template(name, globals)
  File "/home/airflow/.local/lib/python3.7/site-packages/jinja2/environment.py", line 958, in _load_template
    template = self.loader.load(self, name, self.make_globals(globals))
  File "/home/airflow/.local/lib/python3.7/site-packages/jinja2/loaders.py", line 125, in load
    source, filename, uptodate = self.get_source(environment, name)
  File "/home/airflow/.local/lib/python3.7/site-packages/jinja2/loaders.py", line 214, in get_source
    raise TemplateNotFound(template)
jinja2.exceptions.TemplateNotFound: bash /script/date_print.sh
[2025-02-05 03:52:14,280] {taskinstance.py:1400} INFO - Marking task as UP_FOR_RETRY. dag_id=example_dag, task_id=execute_remote_script, execution_date=20250205T035212, start_date=20250205T035214, end_date=20250205T035214
[2025-02-05 03:52:14,284] {standard_task_runner.py:97} ERROR - Failed to execute job 40 for task execute_remote_script (bash /script/date_print.sh; 230)
[2025-02-05 03:52:14,324] {local_task_job.py:156} INFO - Task exited with return code 1
[2025-02-05 03:52:14,338] {local_task_job.py:273} INFO - 0 downstream tasks scheduled from follow-on schedule check
